[2023-03-04T14:07:39.760+0000] {taskinstance.py:1083} INFO - Dependencies all met for <TaskInstance: dag_python_operator_v3.greet manual__2023-03-04T14:02:15.077139+00:00 [queued]>
[2023-03-04T14:07:39.775+0000] {taskinstance.py:1083} INFO - Dependencies all met for <TaskInstance: dag_python_operator_v3.greet manual__2023-03-04T14:02:15.077139+00:00 [queued]>
[2023-03-04T14:07:39.775+0000] {taskinstance.py:1279} INFO - 
--------------------------------------------------------------------------------
[2023-03-04T14:07:39.775+0000] {taskinstance.py:1280} INFO - Starting attempt 3 of 8
[2023-03-04T14:07:39.775+0000] {taskinstance.py:1281} INFO - 
--------------------------------------------------------------------------------
[2023-03-04T14:07:39.797+0000] {taskinstance.py:1300} INFO - Executing <Task(PythonOperator): greet> on 2023-03-04 14:02:15.077139+00:00
[2023-03-04T14:07:39.804+0000] {standard_task_runner.py:55} INFO - Started process 3074 to run task
[2023-03-04T14:07:39.808+0000] {standard_task_runner.py:82} INFO - Running: ['***', 'tasks', 'run', 'dag_python_operator_v3', 'greet', 'manual__2023-03-04T14:02:15.077139+00:00', '--job-id', '13', '--raw', '--subdir', 'DAGS_FOLDER/***_python.py', '--cfg-path', '/tmp/tmp238l21hy']
[2023-03-04T14:07:39.811+0000] {standard_task_runner.py:83} INFO - Job 13: Subtask greet
[2023-03-04T14:07:39.918+0000] {task_command.py:388} INFO - Running <TaskInstance: dag_python_operator_v3.greet manual__2023-03-04T14:02:15.077139+00:00 [running]> on host 07bffc7e5092
[2023-03-04T14:07:40.038+0000] {taskinstance.py:1509} INFO - Exporting the following env vars:
AIRFLOW_CTX_DAG_OWNER=aditya
AIRFLOW_CTX_DAG_ID=dag_python_operator_v3
AIRFLOW_CTX_TASK_ID=greet
AIRFLOW_CTX_EXECUTION_DATE=2023-03-04T14:02:15.077139+00:00
AIRFLOW_CTX_TRY_NUMBER=3
AIRFLOW_CTX_DAG_RUN_ID=manual__2023-03-04T14:02:15.077139+00:00
[2023-03-04T14:07:40.039+0000] {taskinstance.py:1768} ERROR - Task failed with exception
Traceback (most recent call last):
  File "/home/airflow/.local/lib/python3.7/site-packages/airflow/operators/python.py", line 175, in execute
    return_value = self.execute_callable()
  File "/home/airflow/.local/lib/python3.7/site-packages/airflow/operators/python.py", line 192, in execute_callable
    return self.python_callable(*self.op_args, **self.op_kwargs)
  File "/opt/airflow/dags/airflow_python.py", line 14, in greet
    name=ti.xcoms_pull(task_ids='get_name')
AttributeError: 'TaskInstance' object has no attribute 'xcoms_pull'
[2023-03-04T14:07:40.052+0000] {taskinstance.py:1323} INFO - Marking task as UP_FOR_RETRY. dag_id=dag_python_operator_v3, task_id=greet, execution_date=20230304T140215, start_date=20230304T140739, end_date=20230304T140740
[2023-03-04T14:07:40.069+0000] {standard_task_runner.py:105} ERROR - Failed to execute job 13 for task greet ('TaskInstance' object has no attribute 'xcoms_pull'; 3074)
[2023-03-04T14:07:40.102+0000] {local_task_job.py:208} INFO - Task exited with return code 1
[2023-03-04T14:07:40.130+0000] {taskinstance.py:2578} INFO - 0 downstream tasks scheduled from follow-on schedule check
