[2023-03-04T14:02:17.693+0000] {taskinstance.py:1083} INFO - Dependencies all met for <TaskInstance: dag_python_operator_v3.greet scheduled__2023-03-03T00:00:00+00:00 [queued]>
[2023-03-04T14:02:17.720+0000] {taskinstance.py:1083} INFO - Dependencies all met for <TaskInstance: dag_python_operator_v3.greet scheduled__2023-03-03T00:00:00+00:00 [queued]>
[2023-03-04T14:02:17.720+0000] {taskinstance.py:1279} INFO - 
--------------------------------------------------------------------------------
[2023-03-04T14:02:17.720+0000] {taskinstance.py:1280} INFO - Starting attempt 1 of 6
[2023-03-04T14:02:17.721+0000] {taskinstance.py:1281} INFO - 
--------------------------------------------------------------------------------
[2023-03-04T14:02:17.749+0000] {taskinstance.py:1300} INFO - Executing <Task(PythonOperator): greet> on 2023-03-03 00:00:00+00:00
[2023-03-04T14:02:17.755+0000] {standard_task_runner.py:55} INFO - Started process 2718 to run task
[2023-03-04T14:02:17.760+0000] {standard_task_runner.py:82} INFO - Running: ['***', 'tasks', 'run', 'dag_python_operator_v3', 'greet', 'scheduled__2023-03-03T00:00:00+00:00', '--job-id', '10', '--raw', '--subdir', 'DAGS_FOLDER/***_python.py', '--cfg-path', '/tmp/tmpchplg0bz']
[2023-03-04T14:02:17.762+0000] {standard_task_runner.py:83} INFO - Job 10: Subtask greet
[2023-03-04T14:02:17.881+0000] {task_command.py:388} INFO - Running <TaskInstance: dag_python_operator_v3.greet scheduled__2023-03-03T00:00:00+00:00 [running]> on host 07bffc7e5092
[2023-03-04T14:02:18.032+0000] {taskinstance.py:1509} INFO - Exporting the following env vars:
AIRFLOW_CTX_DAG_OWNER=aditya
AIRFLOW_CTX_DAG_ID=dag_python_operator_v3
AIRFLOW_CTX_TASK_ID=greet
AIRFLOW_CTX_EXECUTION_DATE=2023-03-03T00:00:00+00:00
AIRFLOW_CTX_TRY_NUMBER=1
AIRFLOW_CTX_DAG_RUN_ID=scheduled__2023-03-03T00:00:00+00:00
[2023-03-04T14:02:18.034+0000] {taskinstance.py:1768} ERROR - Task failed with exception
Traceback (most recent call last):
  File "/home/airflow/.local/lib/python3.7/site-packages/airflow/operators/python.py", line 175, in execute
    return_value = self.execute_callable()
  File "/home/airflow/.local/lib/python3.7/site-packages/airflow/operators/python.py", line 192, in execute_callable
    return self.python_callable(*self.op_args, **self.op_kwargs)
  File "/opt/airflow/dags/airflow_python.py", line 14, in greet
    name=ti.xcoms_pull(task_ids='get_name')
AttributeError: 'TaskInstance' object has no attribute 'xcoms_pull'
[2023-03-04T14:02:18.058+0000] {taskinstance.py:1323} INFO - Marking task as UP_FOR_RETRY. dag_id=dag_python_operator_v3, task_id=greet, execution_date=20230303T000000, start_date=20230304T140217, end_date=20230304T140218
[2023-03-04T14:02:18.083+0000] {standard_task_runner.py:105} ERROR - Failed to execute job 10 for task greet ('TaskInstance' object has no attribute 'xcoms_pull'; 2718)
[2023-03-04T14:02:18.097+0000] {local_task_job.py:208} INFO - Task exited with return code 1
[2023-03-04T14:02:18.138+0000] {taskinstance.py:2578} INFO - 0 downstream tasks scheduled from follow-on schedule check
